<?xml version="1.0" ?>
<robot xmlns:xacro="http://www.ros.org/wiki/xacro" name="ovidius_v1">

<!-- Builds only baselink for OVIDIUS Manipulator -->

<link name="world"/>

<joint name="world__base_link" type="revolute">
<origin rpy="0 0 0" xyz="0 0 0"/>
<parent link="world"/>
<child link="base_link"/>
<axis xyz="0 0 1"/>
<limit effort="55" lower="-2" upper="2" velocity="4.0841"/>
<dynamics damping="0.5"/>
</joint>

<link name="base_link">
    <inertial>
      <origin rpy="0 0 0" xyz="0.00205 0.00373 0.020774"/>
      <mass value ="0.500" />
      <inertia ixx="5.063e-004" ixy="2.773e-005" ixz="7.042e-007" iyy="5.387e-004" iyz="1.237e-006" izz="7.207e-004"/>
    </inertial>
    <visual>
      <origin rpy="0 0 0.5" xyz="0 0 0"/>
      <geometry>
        <mesh filename="/home/nikos/PhD/projects/Parametric_Simulation_Model_SMM/baselink/ovidius_smm_baselink.stl" scale="0.001 0.001 0.001"/>
      </geometry>
      <material name="gray">
        <color rgba="0.5 0.5 0.5 0.9"/>
      </material>
    </visual>
</link>

</robot>