<?xml version="1.0" ?>
<robot xmlns:xacro="http://www.ros.org/wiki/xacro">
 
<!-- ALL components used to assemble the Ovidius SMM are defined here. This file should be xacro:included in each xacro:assembly robot urdf file! -->

<!-- MASS parameters for Pseudojoint Design-->
<xacro:property name="pseudo_mass_static" value="2.2036439"/>
<xacro:property name="pseudo_mass_moving" value="0.4450127"/>

<xacro:property name="active_mass_static" value="0.892"/>
<xacro:property name="active_mass_moving" value="0.102"/>

<!-- Pseudo static block-->
<xacro:macro name="pseudo_static_link_mesh" params="name origin_xyz origin_rpy">
    <link name="${name}">
      <inertial>
        <origin rpy="0 0 0" xyz="0 0 0.09"/>
        <mass value ="${pseudo_mass_static}" />
        <inertia ixx="3.5655174315e-07" ixy="3.0094534019e-15" ixz="-3.0659548585e-16" iyy="8.1971725028e-7" iyz="1.0236492333e-16" izz="5.0684999189e-07"/>
      </inertial>
      <visual>
        <origin rpy="${origin_rpy}" xyz="${origin_xyz}" />
        <geometry>
          <mesh filename="/home/nikos/PhD/projects/Parametric_Simulation_Model_SMM/Pseudos/pjoint1_static.stl" scale="0.001 0.001 0.001"/>
        </geometry>
              <material name="silver">
        <color rgba="0.753 0.753 0.753 0.5"/>
      </material>
      </visual>
    </link>
</xacro:macro>

<!-- Pseudo moving block-->
<xacro:macro name="pseudo_moving_link_mesh" params="name origin_xyz origin_rpy">
    <link name="${name}">
      <inertial>
        <origin rpy="0 0 0" xyz="0 0 0.04"/>
        <mass value ="${pseudo_mass_moving}" />
        <inertia ixx="1.345843e-07" ixy="1.399547e-14" ixz="-2.461662e-15" iyy="1.577317e-7" iyz="2.024057e-13" izz="1.101806e-7"/>
      </inertial>
      <visual>
        <origin rpy="${origin_rpy}" xyz="${origin_xyz}" />
        <geometry>
          <mesh filename="/home/nikos/PhD/projects/Parametric_Simulation_Model_SMM/Pseudos/pjoint1_moveable.stl" scale="0.001 0.001 0.001"/>
        </geometry>
        <material name="lime">
          <color rgba="1 1 0 1"/>
        </material>
      </visual>
    </link>
</xacro:macro>

<!-- Synthetic joint parameters-->
 <xacro:macro name="synthetic_joint_name" params="synthetic_name  synthetic_origin_rpy synthetic_origin_xyz synthetic_parent synthetic_child">
    <joint name="${synthetic_name}" type="fixed">
      <origin rpy="${synthetic_origin_rpy}" xyz="${synthetic_origin_xyz}" />
      <parent link="${synthetic_parent}" />
      <child link="${synthetic_child}" />
    </joint>
</xacro:macro>

<!-- Pseudojoint joint angle congiguration -->
<xacro:macro name="pseudo_joint_name" params="pseudo_name  pseudo_origin_rpy pseudo_origin_xyz pseudo_parent pseudo_child">
<joint name="${pseudo_name}" type="fixed">
    <origin rpy="${pseudo_origin_rpy}" xyz="${pseudo_origin_xyz}"/>
    <parent link="${pseudo_parent}"/>
    <child link="${pseudo_child}"/>
</joint>
</xacro:macro>

<!-- Fixed assembly parameters-->
 <xacro:macro name="assembly_active_module2pseudo" params="active_assembly_name  active_assembly_origin_rpy active_assembly_origin_xyz active_assembly_parent active_assembly_child">
    <joint name="${active_assembly_name}" type="fixed">
      <origin rpy="${active_assembly_origin_rpy}" xyz="${active_assembly_origin_xyz}" />
      <parent link="${active_assembly_parent}" />
      <child link="${active_assembly_child}" />
    </joint>
</xacro:macro>

<!-- Active static block-->
<xacro:macro name="active_static_link_mesh" params="name origin_xyz origin_rpy">
    <link name="${name}">
      <inertial>
        <origin rpy="0 0 0" xyz="0 0 0"/>
        <mass value ="${active_mass_static}" />
        <inertia ixx="0.001" ixy="-1.292e-11" ixz="3.624e-12" iyy="4.195e-04" iyz="-9.613e-06" izz="0.001"/>
      </inertial>
      <visual>
        <origin rpy="${origin_rpy}" xyz="${origin_xyz}" />
        <geometry>
          <mesh filename="/home/nikos/PhD/projects/Parametric_Simulation_Model_SMM/Active/active_module_fixed.stl" scale="0.001 0.001 0.001"/>
        </geometry>
              <material name="lightblack">
        <color rgba="0.25 0.25 0.25 0.25"/>
      </material>
      </visual>
    </link>
</xacro:macro>

<!-- Active moving block-->
<xacro:macro name="active_moving_link_mesh" params="name origin_xyz origin_rpy">
    <link name="${name}">
      <inertial>
        <origin rpy="0 0 0" xyz="0 0 0"/>
        <mass value ="${active_mass_moving}" />
        <inertia ixx="3.103e-04" ixy="-3.374e-13" ixz="1.202e-12" iyy="3.187e-04" iyz="8.958e-06" izz="5.995e-05"/>
      </inertial>
      <visual>
        <origin rpy="${origin_rpy}" xyz="${origin_xyz}" />
        <geometry>
          <mesh filename="/home/nikos/PhD/projects/Parametric_Simulation_Model_SMM/Active/active_module_moving.stl" scale="0.001 0.001 0.001"/>
        </geometry>
        <material name="black">
          <color rgba="0.1 0.1 0.1 1"/>
        </material>
      </visual>
    </link>
</xacro:macro>

<!-- Synthetic joint parameters-->
 <xacro:macro name="dxlPROp_joint" params="active_name  active_origin_rpy active_origin_xyz active_parent active_child">
    <joint name="${active_name}" type="revolute">
      <origin rpy="${active_origin_rpy}" xyz="${active_origin_xyz}" />
      <parent link="${active_parent}" />
      <child link="${active_child}" />
      <axis xyz="1 0 0"/>
      <limit effort="55" lower="-2" upper="2" velocity="4.0841"/>
      <dynamics damping="0.5"/>
    </joint>
</xacro:macro>

</robot>