<?xml version="1.0" encoding="utf-8"?>
<!-- =================================================================================== -->
<!-- |    This document was autogenerated by xacro from conditioned_parameterized_SMM_assembly.xacro | -->
<!-- |    EDITING THIS FILE BY HAND IS NOT RECOMMENDED                                 | -->
<!-- =================================================================================== -->
<robot name="ovidius_smm">
  <!--Builds SMM structure using conditions. INPUT: Structure notation string. Code evaluates string elements and continues the robot assembly. Notation string is presented in notation_string.txt -->
  <!-- START - Include -->
  <!-- ALL components used to assemble the Ovidius SMM are defined here. This file should be xacro:included in each xacro:assembly robot urdf file! -->
  <!-- III.1	ROBOT to be generated to URDF model-->
  <!-- ROBOT DESCRIPTION-->
  <link name="world"/>
  <!-- S -0- This is first revolute joint -->
  <joint name="world__base_link" type="revolute">
    <origin rpy="0 0 0" xyz="0 0 0"/>
    <parent link="world"/>
    <child link="base_link"/>
    <axis xyz="0 0 1"/>
    <limit effort="55" lower="-2" upper="2" velocity="4.0841"/>
    <dynamics damping="0.5"/>
  </joint>
  <!-- METAMORPHIC LINK 1: BODY "base_link" AND the first pseudo are ALWAYS fixed-->
  <link name="base_link">
    <inertial>
      <origin rpy="0 0 0" xyz="0.00205 0.00373 0.020774"/>
      <mass value="0.500"/>
      <inertia ixx="5.063e-004" ixy="2.773e-005" ixz="7.042e-007" iyy="5.387e-004" iyz="1.237e-006" izz="7.207e-004"/>
    </inertial>
    <visual>
      <origin rpy="0 0 0.5" xyz="0 0 0"/>
      <geometry>
        <mesh filename="/home/nikos/PhD/projects/Parametric_Simulation_Model_SMM/baselink/ovidius_smm_baselink.stl" scale="0.001 0.001 0.001"/>
      </geometry>
      <material name="gray">
        <color rgba="0.5 0.5 0.5 0.9"/>
      </material>
    </visual>
  </link>
  <!-- if pseudo in this position of structure chain exists continue checking for assembly details -->
  <joint name="base_link__pseudo_a" type="fixed">
    <origin rpy="0 0 0" xyz="0 0 0.048"/>
    <parent link="base_link"/>
    <child link="pseudo_a"/>
  </joint>
  <link name="pseudo_a">
    <inertial>
      <origin rpy="0 0 0" xyz="0 0 0"/>
      <mass value="2.2036439"/>
      <inertia ixx="3.5655174315e-07" ixy="3.0094534019e-15" ixz="-3.0659548585e-16" iyy="8.1971725028e-7" iyz="1.0236492333e-16" izz="5.0684999189e-07"/>
    </inertial>
    <visual>
      <origin rpy="1.5708 0 0" xyz="-0.0375 0.2 -0.05"/>
      <geometry>
        <mesh filename="/home/nikos/PhD/projects/Parametric_Simulation_Model_SMM/Pseudos/pjoint1_static.stl" scale="0.001 0.001 0.001"/>
      </geometry>
      <material name="silver">
        <color rgba="0.753 0.753 0.753 0.5"/>
      </material>
    </visual>
  </link>
  <joint name="pseudo_a__pseudo_b" type="fixed">
    <origin rpy="2.5708 0 0" xyz="0 0.025 0.118"/>
    <parent link="pseudo_a"/>
    <child link="pseudo_b"/>
  </joint>
  <link name="pseudo_b">
    <inertial>
      <origin rpy="0 0 0" xyz="0 0 0"/>
      <mass value="0.4450127"/>
      <inertia ixx="1.345843e-07" ixy="1.399547e-14" ixz="-2.461662e-15" iyy="1.577317e-7" iyz="2.024057e-13" izz="1.101806e-7"/>
    </inertial>
    <visual>
      <origin rpy="0 0 0" xyz="-0.061 -0.167 -0.177"/>
      <geometry>
        <mesh filename="/home/nikos/PhD/projects/Parametric_Simulation_Model_SMM/Pseudos/pjoint1_moveable.stl" scale="0.001 0.001 0.001"/>
      </geometry>
      <material name="lime">
        <color rgba="1 1 0 1"/>
      </material>
    </visual>
  </link>
</robot>

